Workbook

Sheet Ex-Pump Prices 4th May 2026
B2: NATIONAL PETROLEUM AUTHORITY
B6: EX-PUMP PRICES OF OMCs/LPGMCs AS OF 4th MAY 2026
B8: NO. | C8: COMPANY | D8: REGULAR PETROL - RON 91 (GHS/Lt) | E8: PREMIUM PETROL - RON 95 (GHS/Lt) | F8: DIESEL (GHS/Lt) | G8: LPG (GHS/Kg) | H8: KEROSENE (GHS/Lt) | I8: MGO Local (GHS/Lt)
B9: 1 | C9: Agapet | D9: 14.46 | E9: - | F9: 16.95 | G9: - | H9: - | I9: -
B10: 2 | C10: Aegis huile | D10: 13.5 | E10: - | F10: 17.5 | G10: - | H10: - | I10: -
B11: 3 | C11: Akara Energy | D11: 13.27 | E11: - | F11: 16.1 | G11: - | H11: - | I11: -
B12: 4 | C12: AI Energy | D12: 13.89 | E12: - | F12: 16.99 | G12: - | H12: - | I12: -
B13: 5 | C13: Allied Oil | D13: 13.25 | E13: - | F13: 15.59 | G13: - | H13: - | I13: -
B14: 6 | C14: Alinco | D14: 13.27 | E14: - | F14: 16.1 | G14: - | H14: - | I14: -
B15: 7 | C15: Alive Gas | D15: - | E15: - | F15: - | G15: 16.56 | H15: - | I15: -
B16: 8 | C16: Aminso Energy | D16: 12 | E16: - | F16: 12.58 | G16: - | H16: - | I16: -
B17: 9 | C17: Anasset | D17: - | E17: - | F17: - | G17: 16.7 | H17: - | I17: -
B18: 10 | C18: Andev | D18: - | E18: - | F18: - | G18: 16.76 | H18: - | I18: -
B19: 11 | C19: Annandale | D19: - | E19: - | F19: - | G19: 16.61 | H19: - | I19: -
B20: 12 | C20: Amdaway | D20: 13.27 | E20: - | F20: 16.1 | G20: - | H20: - | I20: -
B21: 13 | C21: Aminaser oil | D21: 13.27 | E21: - | F21: 16.1 | G21: - | H21: - | I21: -
B22: 14 | C22: Ap Oil & Gas | D22: 13.55 | E22: - | F22: 17.4 | G22: - | H22: - | I22: -
B23: 15 | C23: April Oil Ghana | D23: 13.99 | E23: - | F23: 17.7 | G23: - | H23: - | I23: -
B24: 16 | C24: Benab Oil | D24: 13.25 | E24: - | F24: 15.55 | G24: - | H24: - | I24: -
B25: 17 | C25: Baffour Gas | D25: - | E25: - | F25: - | G25: 17.61 | H25: - | I25: -
B26: 18 | C26: Beap Energy | D26: 13.83 | E26: - | F26: 17.04 | G26: - | H26: - | I26: -
B27: 19 | C27: BG Petroleum | D27: 13.85 | E27: - | F27: 16.5 | G27: - | H27: - | I27: -
B28: 20 | C28: Bloom Petroleum | D28: 13.99 | E28: - | F28: 16.99 | G28: - | H28: - | I28: -
B29: 21 | C29: Brogan Energy | D29: 13.57 | E29: - | F29: 15.55 | G29: - | H29: - | I29: -
B30: 22 | C30: Breedlove | D30: 13.27 | E30: - | F30: 16.1 | G30: - | H30: - | I30: -
B31: 23 | C31: Brent Petroleum | D31: 13.46 | E31: - | F31: 15.79 | G31: - | H31: - | I31: -
B32: 24 | C32: Buffallo | D32: 13.39 | E32: - | F32: 13.99 | G32: - | H32: - | I32: -
B33: 25 | C33: Central Brent | D33: - | E33: - | F33: - | G33: 15.96 | H33: - | I33: -
B34: 26 | C34: Cent Eastern | D34: - | E34: - | F34: - | G34: 16.74 | H34: - | I34: -
B35: 27 | C35: Oil Space | D35: - | E35: - | F35: - | G35: 14.84 | H35: - | I35: -
B36: 28 | C36: Coegan | D36: - | E36: - | F36: - | G36: 17.16 | H36: - | I36: -
B37: 29 | C37: Compass Oleum | D37: 13.85 | E37: - | F37: 16.75 | G37: - | H37: - | I37: -
B38: 30 | C38: Crown Petroleum | D38: 13.99 | E38: - | F38: 16.99 | G38: 18.65 | H38: - | I38: -
B39: 31 | C39: Desert oil | D39: 13.49 | E39: - | F39: 16.49 | G39: - | H39: - | I39: -
B40: 32 | C40: Dejon jones Ltd | D40: 14.21 | E40: - | F40: 16.95 | G40: - | H40: - | I40: -
B41: 33 | C41: Davis Petroleum | D41: 13.99 | E41: - | F41: 16.49 | G41: 15.21 | H41: - | I41: -
B42: 34 | C42: Dukes Petroleum | D42: 13.25 | E42: - | F42: 15.8 | G42: 16.06 | H42: - | I42: -
B43: 35 | C43: E. Windstar Petroleum | D43: 13.4 | E43: - | F43: 16.1 | G43: =G9 -> - | H43: - | I43: -
B44: 36 | C44: Eden Petroleum | D44: 13.45 | E44: - | F44: 17.1 | G44: - | H44: - | I44: -
B45: 37 | C45: Essence Energy | D45: 13.5 | E45: - | F45: 16.8 | G45: - | H45: - | I45: -
...

Sheet Ex-Pump Prices 30th April 2026
B2: NATIONAL PETROLEUM AUTHORITY
B6: EX-PUMP PRICES OF OMCs/LPGMCs AS OF 30th APRIL 2026
B8: NO. | C8: COMPANY | D8: REGULAR PETROL - RON 91 (GHS/Lt) | E8: PREMIUM PETROL - RON 95 (GHS/Lt) | F8: DIESEL (GHS/Lt) | G8: LPG (GHS/Kg) | H8: KEROSENE (GHS/Lt) | I8: MGO Local (GHS/Lt)
B9: 1 | C9: Agapet | D9: 14.46 | E9: - | F9: 16.95 | G9: - | H9: - | I9: -
B10: 2 | C10: Aegis huile | D10: 13.5 | E10: - | F10: 17.5 | G10: - | H10: - | I10: -
B11: 3 | C11: Akara Energy | D11: 13.27 | E11: - | F11: 16.1 | G11: - | H11: - | I11: -
B12: 4 | C12: AI Energy | D12: 13.89 | E12: - | F12: 16.99 | G12: - | H12: - | I12: -
B13: 5 | C13: Allied Oil | D13: 13.27 | E13: - | F13: 16.1 | G13: - | H13: - | I13: -
B14: 6 | C14: Alinco | D14: 13.27 | E14: - | F14: 16.1 | G14: - | H14: - | I14: -
B15: 7 | C15: Alive Gas | D15: - | E15: - | F15: - | G15: 16.56 | H15: - | I15: -
B16: 8 | C16: Aminso Energy | D16: 12 | E16: - | F16: 12.58 | G16: - | H16: - | I16: -
B17: 9 | C17: Anasset | D17: - | E17: - | F17: - | G17: 16.7 | H17: - | I17: -
B18: 10 | C18: Andev | D18: - | E18: - | F18: - | G18: 16.76 | H18: - | I18: -
B19: 11 | C19: Annandale | D19: - | E19: - | F19: - | G19: 16.61 | H19: - | I19: -
B20: 12 | C20: Amdaway | D20: 13.27 | E20: - | F20: 16.1 | G20: - | H20: - | I20: -
B21: 13 | C21: Aminaser oil | D21: 13.27 | E21: - | F21: 16.1 | G21: - | H21: - | I21: -
B22: 14 | C22: Ap Oil & Gas | D22: 13.55 | E22: - | F22: 17.4 | G22: - | H22: - | I22: -
B23: 15 | C23: April Oil Ghana | D23: 13.99 | E23: - | F23: 17.7 | G23: - | H23: - | I23: -
B24: 16 | C24: Benab Oil | D24: 13.27 | E24: - | F24: 16.1 | G24: - | H24: - | I24: -
B25: 17 | C25: Baffour Gas | D25: - | E25: - | F25: - | G25: 17.61 | H25: - | I25: -
B26: 18 | C26: Beap Energy | D26: 13.83 | E26: - | F26: 17.04 | G26: - | H26: - | I26: -
B27: 19 | C27: BG Petroleum | D27: 13.85 | E27: - | F27: 16.5 | G27: - | H27: - | I27: -
B28: 20 | C28: Bloom Petroleum | D28: 13.99 | E28: - | F28: 16.99 | G28: - | H28: - | I28: -
B29: 21 | C29: Brogan Energy | D29: 13.57 | E29: - | F29: 15.55 | G29: - | H29: - | I29: -
B30: 22 | C30: Breedlove | D30: 13.27 | E30: - | F30: 16.1 | G30: - | H30: - | I30: -
B31: 23 | C31: Brent Petroleum | D31: 13.46 | E31: - | F31: 15.79 | G31: - | H31: - | I31: -
B32: 24 | C32: Buffallo | D32: 13.39 | E32: - | F32: 13.99 | G32: - | H32: - | I32: -
B33: 25 | C33: Central Brent | D33: - | E33: - | F33: - | G33: 15.96 | H33: - | I33: -
B34: 26 | C34: Cent Eastern | D34: - | E34: - | F34: - | G34: 16.74 | H34: - | I34: -
B35: 27 | C35: Oil Space | D35: - | E35: - | F35: - | G35: 14.84 | H35: - | I35: -
B36: 28 | C36: Coegan | D36: - | E36: - | F36: - | G36: 17.16 | H36: - | I36: -
B37: 29 | C37: Compass Oleum | D37: 13.85 | E37: - | F37: 16.75 | G37: - | H37: - | I37: -
B38: 30 | C38: Crown Petroleum | D38: 13.99 | E38: - | F38: 16.99 | G38: 18.65 | H38: - | I38: -
B39: 31 | C39: Desert oil | D39: 13.49 | E39: - | F39: 16.49 | G39: - | H39: - | I39: -
B40: 32 | C40: Dejon jones Ltd | D40: 14.21 | E40: - | F40: 16.95 | G40: - | H40: - | I40: -
B41: 33 | C41: Davis Petroleum | D41: 13.99 | E41: - | F41: 16.99 | G41: 15.21 | H41: - | I41: -
B42: 34 | C42: Dukes Petroleum | D42: 13.27 | E42: - | F42: 16.1 | G42: 16.06 | H42: - | I42: -
B43: 35 | C43: E. Windstar Petroleum | D43: 13.4 | E43: - | F43: 16.1 | G43: =G9 -> - | H43: - | I43: -
B44: 36 | C44: Eden Petroleum | D44: 13.45 | E44: - | F44: 17.1 | G44: - | H44: - | I44: -
B45: 37 | C45: Essence Energy | D45: 13.5 | E45: - | F45: 16.8 | G45: - | H45: - | I45: -
...

Sheet Ex-Pump Prices 29th April 2026
B2: NATIONAL PETROLEUM AUTHORITY
B6: EX-PUMP PRICES OF OMCs/LPGMCs AS OF 29th APRIL 2026
B8: NO. | C8: COMPANY | D8: REGULAR PETROL - RON 91 (GHS/Lt) | E8: PREMIUM PETROL - RON 95 (GHS/Lt) | F8: DIESEL (GHS/Lt) | G8: LPG (GHS/Kg) | H8: KEROSENE (GHS/Lt) | I8: MGO Local (GHS/Lt)
B9: 1 | C9: Agapet | D9: 14.46 | E9: - | F9: 16.95 | G9: - | H9: - | I9: -
B10: 2 | C10: Aegis huile | D10: 13.5 | E10: - | F10: 17.5 | G10: - | H10: - | I10: -
B11: 3 | C11: Akara Energy | D11: 13.27 | E11: - | F11: 16.1 | G11: - | H11: - | I11: -
B12: 4 | C12: AI Energy | D12: 13.89 | E12: - | F12: 16.99 | G12: - | H12: - | I12: -
B13: 5 | C13: Allied Oil | D13: 13.27 | E13: - | F13: 16.1 | G13: - | H13: - | I13: -
B14: 6 | C14: Alinco | D14: 13.27 | E14: - | F14: 16.1 | G14: - | H14: - | I14: -
B15: 7 | C15: Alive Gas | D15: - | E15: - | F15: - | G15: 16.56 | H15: - | I15: -
B16: 8 | C16: Aminso Energy | D16: 12 | E16: - | F16: 12.58 | G16: - | H16: - | I16: -
B17: 9 | C17: Anasset | D17: - | E17: - | F17: - | G17: 16.7 | H17: - | I17: -
B18: 10 | C18: Andev | D18: - | E18: - | F18: - | G18: 16.76 | H18: - | I18: -
B19: 11 | C19: Annandale | D19: - | E19: - | F19: - | G19: 16.61 | H19: - | I19: -
B20: 12 | C20: Amdaway | D20: 13.27 | E20: - | F20: 16.1 | G20: - | H20: - | I20: -
B21: 13 | C21: Aminaser oil | D21: 13.27 | E21: - | F21: 16.1 | G21: - | H21: - | I21: -
B22: 14 | C22: Ap Oil & Gas | D22: 13.55 | E22: - | F22: 17.4 | G22: - | H22: - | I22: -
B23: 15 | C23: April Oil Ghana | D23: 13.99 | E23: - | F23: 17.7 | G23: - | H23: - | I23: -
B24: 16 | C24: Benab Oil | D24: 13.27 | E24: - | F24: 16.1 | G24: - | H24: - | I24: -
B25: 17 | C25: Baffour Gas | D25: - | E25: - | F25: - | G25: 17.61 | H25: - | I25: -
B26: 18 | C26: Beap Energy | D26: 13.83 | E26: - | F26: 17.04 | G26: - | H26: - | I26: -
B27: 19 | C27: BG Petroleum | D27: 13.85 | E27: - | F27: 16.5 | G27: - | H27: - | I27: -
B28: 20 | C28: Bloom Petroleum | D28: 13.99 | E28: - | F28: 16.99 | G28: - | H28: - | I28: -
B29: 21 | C29: Brogan Energy | D29: 13.57 | E29: - | F29: 15.55 | G29: - | H29: - | I29: -
B30: 22 | C30: Breedlove | D30: 13.27 | E30: - | F30: 16.1 | G30: - | H30: - | I30: -
B31: 23 | C31: Brent Petroleum | D31: 13.46 | E31: - | F31: 17.69 | G31: - | H31: - | I31: -
B32: 24 | C32: Buffallo | D32: 13.39 | E32: - | F32: 13.99 | G32: - | H32: - | I32: -
B33: 25 | C33: Central Brent | D33: - | E33: - | F33: - | G33: 14.11 | H33: - | I33: -
B34: 26 | C34: Cent Eastern | D34: - | E34: - | F34: - | G34: 16.74 | H34: - | I34: -
B35: 27 | C35: Oil Space | D35: - | E35: - | F35: - | G35: 14.84 | H35: - | I35: -
B36: 28 | C36: Coegan | D36: - | E36: - | F36: - | G36: 17.16 | H36: - | I36: -
B37: 29 | C37: Compass Oleum | D37: 13.85 | E37: - | F37: 16.75 | G37: - | H37: - | I37: -
B38: 30 | C38: Crown Petroleum | D38: 13.99 | E38: - | F38: 16.99 | G38: 18.65 | H38: - | I38: -
B39: 31 | C39: Desert oil | D39: 13.49 | E39: - | F39: 16.49 | G39: - | H39: - | I39: -
B40: 32 | C40: Dejon jones Ltd | D40: 14.21 | E40: - | F40: 16.95 | G40: - | H40: - | I40: -
B41: 33 | C41: Davis Petroleum | D41: 13.99 | E41: - | F41: 16.99 | G41: 15.21 | H41: - | I41: -
B42: 34 | C42: Dukes Petroleum | D42: 13.27 | E42: - | F42: 16.1 | G42: 16.06 | H42: - | I42: -
B43: 35 | C43: E. Windstar Petroleum | D43: 13.4 | E43: - | F43: 16.1 | G43: =G9 -> - | H43: - | I43: -
B44: 36 | C44: Eden Petroleum | D44: 13.45 | E44: - | F44: 17.1 | G44: - | H44: - | I44: -
B45: 37 | C45: Essence Energy | D45: 13.5 | E45: - | F45: 16.8 | G45: - | H45: - | I45: -
...

Sheet Ex-Pump Prices 28th April 2026
B2: NATIONAL PETROLEUM AUTHORITY
B6: EX-PUMP PRICES OF OMCs/LPGMCs AS OF 28th APRIL 2026
B8: NO. | C8: COMPANY | D8: REGULAR PETROL - RON 91 (GHS/Lt) | E8: PREMIUM PETROL - RON 95 (GHS/Lt) | F8: DIESEL (GHS/Lt) | G8: LPG (GHS/Kg) | H8: KEROSENE (GHS/Lt) | I8: MGO Local (GHS/Lt)
B9: 1 | C9: Agapet | D9: 14.46 | E9: - | F9: 16.95 | G9: - | H9: - | I9: -
B10: 2 | C10: Aegis huile | D10: 13.5 | E10: - | F10: 17.5 | G10: - | H10: - | I10: -
B11: 3 | C11: Akara Energy | D11: 13.27 | E11: - | F11: 16.1 | G11: - | H11: - | I11: -
B12: 4 | C12: AI Energy | D12: 13.89 | E12: - | F12: 16.99 | G12: - | H12: - | I12: -
B13: 5 | C13: Allied Oil | D13: 13.27 | E13: - | F13: 16.1 | G13: - | H13: - | I13: -
B14: 6 | C14: Alinco | D14: 13.27 | E14: - | F14: 16.1 | G14: - | H14: - | I14: -
B15: 7 | C15: Alive Gas | D15: - | E15: - | F15: - | G15: 16.56 | H15: - | I15: -
B16: 8 | C16: Aminso Energy | D16: 12 | E16: - | F16: 12.58 | G16: - | H16: - | I16: -
B17: 9 | C17: Anasset | D17: - | E17: - | F17: - | G17: 16.7 | H17: - | I17: -
B18: 10 | C18: Andev | D18: - | E18: - | F18: - | G18: 16.76 | H18: - | I18: -
B19: 11 | C19: Annandale | D19: - | E19: - | F19: - | G19: 16.61 | H19: - | I19: -
B20: 12 | C20: Amdaway | D20: 13.27 | E20: - | F20: 16.1 | G20: - | H20: - | I20: -
B21: 13 | C21: Aminaser oil | D21: 13.27 | E21: - | F21: 16.1 | G21: - | H21: - | I21: -
B22: 14 | C22: Ap Oil & Gas | D22: 13.55 | E22: - | F22: 17.4 | G22: - | H22: - | I22: -
B23: 15 | C23: April Oil Ghana | D23: 13.99 | E23: - | F23: 17.7 | G23: - | H23: - | I23: -
B24: 16 | C24: Benab Oil | D24: 13.27 | E24: - | F24: 16.1 | G24: - | H24: - | I24: -
B25: 17 | C25: Baffour Gas | D25: - | E25: - | F25: - | G25: 17.61 | H25: - | I25: -
B26: 18 | C26: Beap Energy | D26: 13.73 | E26: - | F26: 17.39 | G26: - | H26: - | I26: -
B27: 19 | C27: BG Petroleum | D27: 13.85 | E27: - | F27: 17.97 | G27: - | H27: - | I27: -
B28: 20 | C28: Bloom Petroleum | D28: 13.99 | E28: - | F28: 16.99 | G28: - | H28: - | I28: -
B29: 21 | C29: Brogan Energy | D29: 13.57 | E29: - | F29: 15.55 | G29: - | H29: - | I29: -
B30: 22 | C30: Breedlove | D30: 13.27 | E30: - | F30: 16.1 | G30: - | H30: - | I30: -
B31: 23 | C31: Brent Petroleum | D31: 13.46 | E31: - | F31: 17.69 | G31: - | H31: - | I31: -
B32: 24 | C32: Buffallo | D32: 13.39 | E32: - | F32: 13.99 | G32: - | H32: - | I32: -
B33: 25 | C33: Central Brent | D33: - | E33: - | F33: - | G33: 14.11 | H33: - | I33: -
B34: 26 | C34: Cent Eastern | D34: - | E34: - | F34: - | G34: 16.74 | H34: - | I34: -
B35: 27 | C35: Oil Space | D35: - | E35: - | F35: - | G35: 14.84 | H35: - | I35: -
B36: 28 | C36: Coegan | D36: - | E36: - | F36: - | G36: 17.16 | H36: - | I36: -
B37: 29 | C37: Compass Oleum | D37: 13.85 | E37: - | F37: 16.75 | G37: - | H37: - | I37: -
B38: 30 | C38: Crown Petroleum | D38: 13.99 | E38: - | F38: 16.99 | G38: 18.65 | H38: - | I38: -
B39: 31 | C39: Desert oil | D39: 13.49 | E39: - | F39: 16.49 | G39: - | H39: - | I39: -
B40: 32 | C40: Dejon jones Ltd | D40: 14.21 | E40: - | F40: 16.95 | G40: - | H40: - | I40: -
B41: 33 | C41: Davis Petroleum | D41: 13.99 | E41: - | F41: 16.99 | G41: 15.21 | H41: - | I41: -
B42: 34 | C42: Dukes Petroleum | D42: 13.27 | E42: - | F42: 16.1 | G42: 16.06 | H42: - | I42: -
B43: 35 | C43: E. Windstar Petroleum | D43: 13.4 | E43: - | F43: 16.1 | G43: =G9 -> - | H43: - | I43: -
B44: 36 | C44: Eden Petroleum | D44: 13.45 | E44: - | F44: 17.1 | G44: - | H44: - | I44: -
B45: 37 | C45: Essence Energy | D45: 13.5 | E45: - | F45: 16.8 | G45: - | H45: - | I45: -
...

Sheet Ex-Pump Prices 27th April 2026
B2: NATIONAL PETROLEUM AUTHORITY
B6: EX-PUMP PRICES OF OMCs/LPGMCs AS OF 27th APRIL 2026
B8: NO. | C8: COMPANY | D8: REGULAR PETROL - RON 91 (GHS/Lt) | E8: PREMIUM PETROL - RON 95 (GHS/Lt) | F8: DIESEL (GHS/Lt) | G8: LPG (GHS/Kg) | H8: KEROSENE (GHS/Lt) | I8: MGO Local (GHS/Lt)
B9: 1 | C9: Agapet | D9: 14.46 | E9: - | F9: 16.95 | G9: - | H9: - | I9: -
B10: 2 | C10: Aegis huile | D10: 13.5 | E10: - | F10: 17.5 | G10: - | H10: - | I10: -
B11: 3 | C11: Akara Energy | D11: 13.27 | E11: - | F11: 16.1 | G11: - | H11: - | I11: -
B12: 4 | C12: AI Energy | D12: 13.89 | E12: - | F12: 16.99 | G12: - | H12: - | I12: -
B13: 5 | C13: Allied Oil | D13: 13.27 | E13: - | F13: 16.1 | G13: - | H13: - | I13: -
B14: 6 | C14: Alinco | D14: 13.27 | E14: - | F14: 16.1 | G14: - | H14: - | I14: -
B15: 7 | C15: Alive Gas | D15: - | E15: - | F15: - | G15: 16.56 | H15: - | I15: -
B16: 8 | C16: Aminso Energy | D16: 12 | E16: - | F16: 12.58 | G16: - | H16: - | I16: -
B17: 9 | C17: Anasset | D17: - | E17: - | F17: - | G17: 16.7 | H17: - | I17: -
B18: 10 | C18: Andev | D18: - | E18: - | F18: - | G18: 16.76 | H18: - | I18: -
B19: 11 | C19: Annandale | D19: - | E19: - | F19: - | G19: 16.61 | H19: - | I19: -
B20: 12 | C20: Amdaway | D20: 13.27 | E20: - | F20: 16.1 | G20: - | H20: - | I20: -
B21: 13 | C21: Aminaser oil | D21: 13.27 | E21: - | F21: 16.1 | G21: - | H21: - | I21: -
B22: 14 | C22: Ap Oil & Gas | D22: 13.55 | E22: - | F22: 17.4 | G22: - | H22: - | I22: -
B23: 15 | C23: April Oil Ghana | D23: 13.99 | E23: - | F23: 17.7 | G23: - | H23: - | I23: -
B24: 16 | C24: Benab Oil | D24: 13.27 | E24: - | F24: 16.1 | G24: - | H24: - | I24: -
B25: 17 | C25: Baffour Gas | D25: - | E25: - | F25: - | G25: 17.61 | H25: - | I25: -
B26: 18 | C26: Beap Energy | D26: 13.73 | E26: - | F26: 17.39 | G26: - | H26: - | I26: -
B27: 19 | C27: BG Petroleum | D27: 13.85 | E27: - | F27: 17.97 | G27: - | H27: - | I27: -
B28: 20 | C28: Bloom Petroleum | D28: 13.99 | E28: - | F28: 16.99 | G28: - | H28: - | I28: -
B29: 21 | C29: Brogan Energy | D29: 13.57 | E29: - | F29: 15.55 | G29: - | H29: - | I29: -
B30: 22 | C30: Breedlove | D30: 13.27 | E30: - | F30: 16.1 | G30: - | H30: - | I30: -
B31: 23 | C31: Brent Petroleum | D31: 13.46 | E31: - | F31: 17.69 | G31: - | H31: - | I31: -
B32: 24 | C32: Buffallo | D32: 13.39 | E32: - | F32: 13.99 | G32: - | H32: - | I32: -
B33: 25 | C33: Central Brent | D33: - | E33: - | F33: - | G33: 14.11 | H33: - | I33: -
B34: 26 | C34: Cent Eastern | D34: - | E34: - | F34: - | G34: 16.74 | H34: - | I34: -
B35: 27 | C35: Oil Space | D35: - | E35: - | F35: - | G35: 14.84 | H35: - | I35: -
B36: 28 | C36: Coegan | D36: - | E36: - | F36: - | G36: 17.16 | H36: - | I36: -
B37: 29 | C37: Compass Oleum | D37: 13.85 | E37: - | F37: 16.75 | G37: - | H37: - | I37: -
B38: 30 | C38: Crown Petroleum | D38: 13.99 | E38: - | F38: 16.99 | G38: 18.65 | H38: - | I38: -
B39: 31 | C39: Desert oil | D39: 13.49 | E39: - | F39: 16.49 | G39: - | H39: - | I39: -
B40: 32 | C40: Dejon jones Ltd | D40: 14.21 | E40: - | F40: 16.95 | G40: - | H40: - | I40: -
B41: 33 | C41: Davis Petroleum | D41: 13.99 | E41: - | F41: 16.99 | G41: 15.21 | H41: - | I41: -
B42: 34 | C42: Dukes Petroleum | D42: 13.27 | E42: - | F42: 16.1 | G42: 16.06 | H42: - | I42: -
B43: 35 | C43: E. Windstar Petroleum | D43: 13.4 | E43: - | F43: 16.1 | G43: =G9 -> - | H43: - | I43: -
B44: 36 | C44: Eden Petroleum | D44: 13.45 | E44: - | F44: 17.1 | G44: - | H44: - | I44: -
B45: 37 | C45: Essence Energy | D45: 13.5 | E45: - | F45: 16.8 | G45: - | H45: - | I45: -
...

Sheet Ex-Pump Prices 24th April 2026
B2: NATIONAL PETROLEUM AUTHORITY
B6: EX-PUMP PRICES OF OMCs/LPGMCs AS OF 24th APRIL 2026
B8: NO. | C8: COMPANY | D8: REGULAR PETROL - RON 91 (GHS/Lt) | E8: PREMIUM PETROL - RON 95 (GHS/Lt) | F8: DIESEL (GHS/Lt) | G8: LPG (GHS/Kg) | H8: KEROSENE (GHS/Lt) | I8: MGO Local (GHS/Lt)
B9: 1 | C9: Agapet | D9: 14.46 | E9: - | F9: 16.95 | G9: - | H9: - | I9: -
B10: 2 | C10: Aegis huile | D10: 13.5 | E10: - | F10: 17.5 | G10: - | H10: - | I10: -
B11: 3 | C11: Akara Energy | D11: 13.27 | E11: - | F11: 16.1 | G11: - | H11: - | I11: -
B12: 4 | C12: AI Energy | D12: 13.89 | E12: - | F12: 16.99 | G12: - | H12: - | I12: -
B13: 5 | C13: Allied Oil | D13: 13.27 | E13: - | F13: 16.1 | G13: - | H13: - | I13: -
B14: 6 | C14: Alinco | D14: 13.27 | E14: - | F14: 16.1 | G14: - | H14: - | I14: -
B15: 7 | C15: Alive Gas | D15: - | E15: - | F15: - | G15: 16.56 | H15: - | I15: -
B16: 8 | C16: Aminso Energy | D16: 12 | E16: - | F16: 12.58 | G16: - | H16: - | I16: -
B17: 9 | C17: Anasset | D17: - | E17: - | F17: - | G17: 16.7 | H17: - | I17: -
B18: 10 | C18: Andev | D18: - | E18: - | F18: - | G18: 16.76 | H18: - | I18: -
B19: 11 | C19: Annandale | D19: - | E19: - | F19: - | G19: 16.61 | H19: - | I19: -
B20: 12 | C20: Amdaway | D20: 13.27 | E20: - | F20: 16.1 | G20: - | H20: - | I20: -
B21: 13 | C21: Aminaser oil | D21: 13.27 | E21: - | F21: 16.1 | G21: - | H21: - | I21: -
B22: 14 | C22: Ap Oil & Gas | D22: 13.55 | E22: - | F22: 17.4 | G22: - | H22: - | I22: -
B23: 15 | C23: April Oil Ghana | D23: 13.99 | E23: - | F23: 17.7 | G23: - | H23: - | I23: -
B24: 16 | C24: Benab Oil | D24: 13.27 | E24: - | F24: 16.1 | G24: - | H24: - | I24: -
B25: 17 | C25: Baffour Gas | D25: - | E25: - | F25: - | G25: 17.61 | H25: - | I25: -
B26: 18 | C26: Beap Energy | D26: 13.73 | E26: - | F26: 17.39 | G26: - | H26: - | I26: -
B27: 19 | C27: BG Petroleum | D27: 13.85 | E27: - | F27: 17.97 | G27: - | H27: - | I27: -
B28: 20 | C28: Bloom Petroleum | D28: 13.99 | E28: - | F28: 16.99 | G28: - | H28: - | I28: -
B29: 21 | C29: Brogan Energy | D29: 13.57 | E29: - | F29: 15.55 | G29: - | H29: - | I29: -
B30: 22 | C30: Breedlove | D30: 13.27 | E30: - | F30: 16.1 | G30: - | H30: - | I30: -
B31: 23 | C31: Brent Petroleum | D31: 13.46 | E31: - | F31: 17.69 | G31: - | H31: - | I31: -
B32: 24 | C32: Buffallo | D32: 13.39 | E32: - | F32: 13.99 | G32: - | H32: - | I32: -
B33: 25 | C33: Central Brent | D33: - | E33: - | F33: - | G33: 14.11 | H33: - | I33: -
B34: 26 | C34: Cent Eastern | D34: - | E34: - | F34: - | G34: 16.74 | H34: - | I34: -
B35: 27 | C35: Oil Space | D35: - | E35: - | F35: - | G35: 14.84 | H35: - | I35: -
B36: 28 | C36: Coegan | D36: - | E36: - | F36: - | G36: 17.16 | H36: - | I36: -
B37: 29 | C37: Compass Oleum | D37: 13.85 | E37: - | F37: 16.75 | G37: - | H37: - | I37: -
B38: 30 | C38: Crown Petroleum | D38: 13.99 | E38: - | F38: 16.99 | G38: 18.65 | H38: - | I38: -
B39: 31 | C39: Desert oil | D39: 13.49 | E39: - | F39: 16.49 | G39: - | H39: - | I39: -
B40: 32 | C40: Dejon jones Ltd | D40: 14.21 | E40: - | F40: 16.95 | G40: - | H40: - | I40: -
B41: 33 | C41: Davis Petroleum | D41: 13.99 | E41: - | F41: 16.99 | G41: 15.21 | H41: - | I41: -
B42: 34 | C42: Dukes Petroleum | D42: 13.27 | E42: - | F42: 16.1 | G42: 16.06 | H42: - | I42: -
B43: 35 | C43: E. Windstar Petroleum | D43: 13.55 | E43: - | F43: 16.99 | G43: =G9 -> - | H43: - | I43: -
B44: 36 | C44: Eden Petroleum | D44: 13.45 | E44: - | F44: 17.1 | G44: - | H44: - | I44: -
B45: 37 | C45: Essence Energy | D45: 13.5 | E45: - | F45: 16.8 | G45: - | H45: - | I45: -
...

Sheet Ex-Pump Prices 23rd April 2026
B2: NATIONAL PETROLEUM AUTHORITY
B6: EX-PUMP PRICES OF OMCs/LPGMCs AS OF 23rd APRIL 2026
B8: NO. | C8: COMPANY | D8: REGULAR PETROL - RON 91 (GHS/Lt) | E8: PREMIUM PETROL - RON 95 (GHS/Lt) | F8: DIESEL (GHS/Lt) | G8: LPG (GHS/Kg) | H8: KEROSENE (GHS/Lt) | I8: MGO Local (GHS/Lt)
B9: 1 | C9: Agapet | D9: 14.46 | E9: - | F9: 16.95 | G9: - | H9: - | I9: -
B10: 2 | C10: Aegis huile | D10: 13.5 | E10: - | F10: 17.5 | G10: - | H10: - | I10: -
B11: 3 | C11: Akara Energy | D11: 13.27 | E11: - | F11: 16.1 | G11: - | H11: - | I11: -
B12: 4 | C12: AI Energy | D12: 13.89 | E12: - | F12: 16.99 | G12: - | H12: - | I12: -
B13: 5 | C13: Allied Oil | D13: 13.27 | E13: - | F13: 16.1 | G13: - | H13: - | I13: -
B14: 6 | C14: Alinco | D14: 13.27 | E14: - | F14: 16.1 | G14: - | H14: - | I14: -
B15: 7 | C15: Alive Gas | D15: - | E15: - | F15: - | G15: 16.56 | H15: - | I15: -
B16: 8 | C16: Aminso Energy | D16: 12 | E16: - | F16: 12.58 | G16: - | H16: - | I16: -
B17: 9 | C17: Anasset | D17: - | E17: - | F17: - | G17: 16.7 | H17: - | I17: -
B18: 10 | C18: Andev | D18: - | E18: - | F18: - | G18: 16.76 | H18: - | I18: -
B19: 11 | C19: Annandale | D19: - | E19: - | F19: - | G19: 16.61 | H19: - | I19: -
B20: 12 | C20: Amdaway | D20: 13.27 | E20: - | F20: 16.1 | G20: - | H20: - | I20: -
B21: 13 | C21: Aminaser oil | D21: 13.27 | E21: - | F21: 16.1 | G21: - | H21: - | I21: -
B22: 14 | C22: Ap Oil & Gas | D22: 13.55 | E22: - | F22: 17.4 | G22: - | H22: - | I22: -
B23: 15 | C23: April Oil Ghana | D23: 13.99 | E23: - | F23: 17.7 | G23: - | H23: - | I23: -
B24: 16 | C24: Benab Oil | D24: 13.27 | E24: - | F24: 16.1 | G24: - | H24: - | I24: -
B25: 17 | C25: Baffour Gas | D25: - | E25: - | F25: - | G25: 17.61 | H25: - | I25: -
B26: 18 | C26: Beap Energy | D26: 13.73 | E26: - | F26: 17.39 | G26: - | H26: - | I26: -
B27: 19 | C27: BG Petroleum | D27: 13.85 | E27: - | F27: 17.97 | G27: - | H27: - | I27: -
B28: 20 | C28: Bloom Petroleum | D28: 13.99 | E28: - | F28: 16.99 | G28: - | H28: - | I28: -
B29: 21 | C29: Brogan Energy | D29: 13.57 | E29: - | F29: 15.55 | G29: - | H29: - | I29: -
B30: 22 | C30: Breedlove | D30: 13.27 | E30: - | F30: 16.1 | G30: - | H30: - | I30: -
B31: 23 | C31: Brent Petroleum | D31: 13.46 | E31: - | F31: 17.69 | G31: - | H31: - | I31: -
B32: 24 | C32: Buffallo | D32: 13.39 | E32: - | F32: 13.99 | G32: - | H32: - | I32: -
B33: 25 | C33: Central Brent | D33: - | E33: - | F33: - | G33: 14.11 | H33: - | I33: -
B34: 26 | C34: Cent Eastern | D34: - | E34: - | F34: - | G34: 16.74 | H34: - | I34: -
B35: 27 | C35: Oil Space | D35: - | E35: - | F35: - | G35: 14.84 | H35: - | I35: -
B36: 28 | C36: Coegan | D36: - | E36: - | F36: - | G36: 17.16 | H36: - | I36: -
B37: 29 | C37: Compass Oleum | D37: 13.85 | E37: - | F37: 16.75 | G37: - | H37: - | I37: -
B38: 30 | C38: Crown Petroleum | D38: 13.99 | E38: - | F38: 16.99 | G38: 18.65 | H38: - | I38: -
B39: 31 | C39: Desert oil | D39: 13.59 | E39: - | F39: 17.69 | G39: - | H39: - | I39: -
B40: 32 | C40: Dejon jones Ltd | D40: 14.21 | E40: - | F40: 16.95 | G40: - | H40: - | I40: -
B41: 33 | C41: Davis Petroleum | D41: 13.99 | E41: - | F41: 16.99 | G41: 15.21 | H41: - | I41: -
B42: 34 | C42: Dukes Petroleum | D42: 13.27 | E42: - | F42: 16.1 | G42: 16.06 | H42: - | I42: -
B43: 35 | C43: E. Windstar Petroleum | D43: 13.55 | E43: - | F43: 16.99 | G43: =G9 -> - | H43: - | I43: -
B44: 36 | C44: Eden Petroleum | D44: 13.45 | E44: - | F44: 17.1 | G44: - | H44: - | I44: -
B45: 37 | C45: Essence Energy | D45: 13.5 | E45: - | F45: 16.8 | G45: - | H45: - | I45: -
...

Sheet Ex-Pump Prices 22nd April 2026
B2: NATIONAL PETROLEUM AUTHORITY
B6: EX-PUMP PRICES OF OMCs/LPGMCs AS OF 22nd APRIL 2026
B8: NO. | C8: COMPANY | D8: REGULAR PETROL - RON 91 (GHS/Lt) | E8: PREMIUM PETROL - RON 95 (GHS/Lt) | F8: DIESEL (GHS/Lt) | G8: LPG (GHS/Kg) | H8: KEROSENE (GHS/Lt) | I8: MGO Local (GHS/Lt)
B9: 1 | C9: Agapet | D9: 14.46 | E9: - | F9: 16.95 | G9: - | H9: - | I9: -
B10: 2 | C10: Aegis huile | D10: 13.5 | E10: - | F10: 17.5 | G10: - | H10: - | I10: -
B11: 3 | C11: Akara Energy | D11: 13.07 | E11: - | F11: 16.05 | G11: - | H11: - | I11: -
B12: 4 | C12: AI Energy | D12: 13.89 | E12: - | F12: 16.99 | G12: - | H12: - | I12: -
B13: 5 | C13: Allied Oil | D13: 13.27 | E13: - | F13: 16.1 | G13: - | H13: - | I13: -
B14: 6 | C14: Alinco | D14: 13.27 | E14: - | F14: 16.1 | G14: - | H14: - | I14: -
B15: 7 | C15: Alive Gas | D15: - | E15: - | F15: - | G15: 16.56 | H15: - | I15: -
B16: 8 | C16: Aminso Energy | D16: 12 | E16: - | F16: 12.58 | G16: - | H16: - | I16: -
B17: 9 | C17: Anasset | D17: =-J5 -> 0 | E17: - | F17: - | G17: 16.7 | H17: - | I17: -
B18: 10 | C18: Andev | D18: - | E18: - | F18: - | G18: 16.76 | H18: - | I18: -
B19: 11 | C19: Annandale | D19: - | E19: - | F19: - | G19: 16.61 | H19: - | I19: -
B20: 12 | C20: Amdaway | D20: 13.27 | E20: - | F20: 16.1 | G20: - | H20: - | I20: -
B21: 13 | C21: Aminaser oil | D21: 13.27 | E21: - | F21: 16.1 | G21: - | H21: - | I21: -
B22: 14 | C22: Ap Oil & Gas | D22: 13.55 | E22: - | F22: 17.4 | G22: - | H22: - | I22: -
B23: 15 | C23: April Oil Ghana | D23: 13.99 | E23: - | F23: 17.7 | G23: - | H23: - | I23: -
B24: 16 | C24: Benab Oil | D24: 13.27 | E24: - | F24: 16.1 | G24: - | H24: - | I24: -
B25: 17 | C25: Baffour Gas | D25: - | E25: - | F25: - | G25: 17.61 | H25: - | I25: -
B26: 18 | C26: Beap Energy | D26: 13.73 | E26: - | F26: 17.39 | G26: - | H26: - | I26: -
B27: 19 | C27: BG Petroleum | D27: 13.85 | E27: - | F27: 17.97 | G27: - | H27: - | I27: -
B28: 20 | C28: Bloom Petroleum | D28: 13.99 | E28: - | F28: 16.99 | G28: - | H28: - | I28: -
B29: 21 | C29: Brogan Energy | D29: 13.57 | E29: - | F29: 15.55 | G29: - | H29: - | I29: -
B30: 22 | C30: Breedlove | D30: 13.27 | E30: - | F30: 16.1 | G30: - | H30: - | I30: -
B31: 23 | C31: Brent Petroleum | D31: 13.46 | E31: - | F31: 17.69 | G31: - | H31: - | I31: -
B32: 24 | C32: Buffallo | D32: 13.39 | E32: - | F32: 13.99 | G32: - | H32: - | I32: -
B33: 25 | C33: Central Brent | D33: - | E33: - | F33: - | G33: 14.11 | H33: - | I33: -
B34: 26 | C34: Cent Eastern | D34: - | E34: - | F34: - | G34: 16.74 | H34: - | I34: -
B35: 27 | C35: Oil Space | D35: - | E35: - | F35: - | G35: 14.84 | H35: - | I35: -
B36: 28 | C36: Coegan | D36: - | E36: - | F36: - | G36: 17.16 | H36: - | I36: -
B37: 29 | C37: Compass Oleum | D37: 13.85 | E37: - | F37: 16.75 | G37: - | H37: - | I37: -
B38: 30 | C38: Crown Petroleum | D38: 13.99 | E38: - | F38: 16.99 | G38: 18.65 | H38: - | I38: -
B39: 31 | C39: Desert oil | D39: 13.59 | E39: - | F39: 17.69 | G39: - | H39: - | I39: -
B40: 32 | C40: Dejon jones Ltd | D40: 14.21 | E40: - | F40: 16.95 | G40: - | H40: - | I40: -
B41: 33 | C41: Davis Petroleum | D41: 13.99 | E41: - | F41: 16.99 | G41: 15.21 | H41: - | I41: -
B42: 34 | C42: Dukes Petroleum | D42: 13.27 | E42: - | F42: 16.1 | G42: 16.06 | H42: - | I42: -
B43: 35 | C43: E. Windstar Petroleum | D43: 13.55 | E43: - | F43: 16.99 | G43: =G9 -> - | H43: - | I43: -
B44: 36 | C44: Eden Petroleum | D44: 13.45 | E44: - | F44: 17.1 | G44: - | H44: - | I44: -
B45: 37 | C45: Essence Energy | D45: 13.5 | E45: - | F45: 16.8 | G45: - | H45: - | I45: -
...

Sheet Ex-Pump Prices 21st April 2026
B2: NATIONAL PETROLEUM AUTHORITY
B6: EX-PUMP PRICES OF OMCs/LPGMCs AS OF 21st APRIL 2026
B8: NO. | C8: COMPANY | D8: REGULAR PETROL - RON 91 (GHS/Lt) | E8: PREMIUM PETROL - RON 95 (GHS/Lt) | F8: DIESEL (GHS/Lt) | G8: LPG (GHS/Kg) | H8: KEROSENE (GHS/Lt) | I8: MGO Local (GHS/Lt)
B9: 1 | C9: Agapet | D9: 14.46 | E9: - | F9: 16.95 | G9: - | H9: - | I9: -
B10: 2 | C10: Aegis huile | D10: 13.5 | E10: - | F10: 17.5 | G10: - | H10: - | I10: -
B11: 3 | C11: Akara Energy | D11: 13.07 | E11: - | F11: 16.05 | G11: - | H11: - | I11: -
B12: 4 | C12: AI Energy | D12: 13.89 | E12: - | F12: 16.99 | G12: - | H12: - | I12: -
B13: 5 | C13: Allied Oil | D13: 13.27 | E13: - | F13: 16.1 | G13: - | H13: - | I13: -
B14: 6 | C14: Alinco | D14: 13.27 | E14: - | F14: 16.1 | G14: - | H14: - | I14: -
B15: 7 | C15: Alive Gas | D15: - | E15: - | F15: - | G15: 16.56 | H15: - | I15: -
B16: 8 | C16: Aminso Energy | D16: 12 | E16: - | F16: 12.58 | G16: - | H16: - | I16: -
B17: 9 | C17: Anasset | D17: =-J5 -> 0 | E17: - | F17: - | G17: 16.7 | H17: - | I17: -
B18: 10 | C18: Andev | D18: - | E18: - | F18: - | G18: 16.76 | H18: - | I18: -
B19: 11 | C19: Annandale | D19: - | E19: - | F19: - | G19: 16.61 | H19: - | I19: -
B20: 12 | C20: Amdaway | D20: 13.56 | E20: - | F20: 17.56 | G20: - | H20: - | I20: -
B21: 13 | C21: Aminaser oil | D21: 13.27 | E21: - | F21: 16.1 | G21: - | H21: - | I21: -
B22: 14 | C22: Ap Oil & Gas | D22: 13.55 | E22: - | F22: 17.4 | G22: - | H22: - | I22: -
B23: 15 | C23: April Oil Ghana | D23: 13.99 | E23: - | F23: 17.7 | G23: - | H23: - | I23: -
B24: 16 | C24: Benab Oil | D24: 13.27 | E24: - | F24: 16.1 | G24: - | H24: - | I24: -
B25: 17 | C25: Baffour Gas | D25: - | E25: - | F25: - | G25: 17.61 | H25: - | I25: -
B26: 18 | C26: Beap Energy | D26: 13.73 | E26: - | F26: 17.39 | G26: - | H26: - | I26: -
B27: 19 | C27: BG Petroleum | D27: 13.85 | E27: - | F27: 17.97 | G27: - | H27: - | I27: -
B28: 20 | C28: Bloom Petroleum | D28: 13.99 | E28: - | F28: 16.99 | G28: - | H28: - | I28: -
B29: 21 | C29: Brogan Energy | D29: 13.57 | E29: - | F29: 15.55 | G29: - | H29: - | I29: -
B30: 22 | C30: Breedlove | D30: 13.27 | E30: - | F30: 16.1 | G30: - | H30: - | I30: -
B31: 23 | C31: Brent Petroleum | D31: 13.46 | E31: - | F31: 17.69 | G31: - | H31: - | I31: -
B32: 24 | C32: Buffallo | D32: 13.39 | E32: - | F32: 13.99 | G32: - | H32: - | I32: -
B33: 25 | C33: Central Brent | D33: - | E33: - | F33: - | G33: 14.11 | H33: - | I33: -
B34: 26 | C34: Cent Eastern | D34: - | E34: - | F34: - | G34: 16.74 | H34: - | I34: -
B35: 27 | C35: Oil Space | D35: - | E35: - | F35: - | G35: 14.84 | H35: - | I35: -
B36: 28 | C36: Coegan | D36: - | E36: - | F36: - | G36: 17.16 | H36: - | I36: -
B37: 29 | C37: Compass Oleum | D37: 13.85 | E37: - | F37: 16.75 | G37: - | H37: - | I37: -
B38: 30 | C38: Crown Petroleum | D38: 13.99 | E38: - | F38: 16.99 | G38: 18.65 | H38: - | I38: -
B39: 31 | C39: Desert oil | D39: 13.59 | E39: - | F39: 17.69 | G39: - | H39: - | I39: -
B40: 32 | C40: Dejon jones Ltd | D40: 14.21 | E40: - | F40: 16.95 | G40: - | H40: - | I40: -
B41: 33 | C41: Davis Petroleum | D41: 13.99 | E41: - | F41: 16.99 | G41: 15.21 | H41: - | I41: -
B42: 34 | C42: Dukes Petroleum | D42: 13.27 | E42: - | F42: 16.1 | G42: 16.06 | H42: - | I42: -
B43: 35 | C43: E. Windstar Petroleum | D43: 13.55 | E43: - | F43: 16.99 | G43: =G9 -> - | H43: - | I43: -
B44: 36 | C44: Eden Petroleum | D44: 13.45 | E44: - | F44: 17.1 | G44: - | H44: - | I44: -
B45: 37 | C45: Essence Energy | D45: 14.3 | E45: - | F45: 18.3 | G45: - | H45: - | I45: -
...

Sheet Ex-Pump Prices 20th April 2026
B2: NATIONAL PETROLEUM AUTHORITY
B6: EX-PUMP PRICES OF OMCs/LPGMCs AS OF 20th APRIL 2026
B8: NO. | C8: COMPANY | D8: REGULAR PETROL - RON 91 (GHS/Lt) | E8: PREMIUM PETROL - RON 95 (GHS/Lt) | F8: DIESEL (GHS/Lt) | G8: LPG (GHS/Kg) | H8: KEROSENE (GHS/Lt) | I8: MGO Local (GHS/Lt)
B9: 1 | C9: Agapet | D9: 14.46 | E9: - | F9: 16.95 | G9: - | H9: - | I9: -
B10: 2 | C10: Aegis huile | D10: 13.5 | E10: - | F10: 17.5 | G10: - | H10: - | I10: -
B11: 3 | C11: Akara Energy | D11: 13.07 | E11: - | F11: 16.05 | G11: - | H11: - | I11: -
B12: 4 | C12: AI Energy | D12: 13.89 | E12: - | F12: 16.99 | G12: - | H12: - | I12: -
B13: 5 | C13: Allied Oil | D13: 13.27 | E13: - | F13: 16.1 | G13: - | H13: - | I13: -
B14: 6 | C14: Alinco | D14: 13.27 | E14: - | F14: 16.1 | G14: - | H14: - | I14: -
B15: 7 | C15: Alive Gas | D15: - | E15: - | F15: - | G15: 16.56 | H15: - | I15: -
B16: 8 | C16: Aminso Energy | D16: 12 | E16: - | F16: 12.58 | G16: - | H16: - | I16: -
B17: 9 | C17: Anasset | D17: =-J5 -> 0 | E17: - | F17: - | G17: 16.7 | H17: - | I17: -
B18: 10 | C18: Andev | D18: - | E18: - | F18: - | G18: 16.76 | H18: - | I18: -
B19: 11 | C19: Annandale | D19: - | E19: - | F19: - | G19: 16.61 | H19: - | I19: -
B20: 12 | C20: Amdaway | D20: 13.56 | E20: - | F20: 17.56 | G20: - | H20: - | I20: -
B21: 13 | C21: Aminaser oil | D21: 13.27 | E21: - | F21: 16.1 | G21: - | H21: - | I21: -
B22: 14 | C22: Ap Oil & Gas | D22: 13.55 | E22: - | F22: 17.4 | G22: - | H22: - | I22: -
B23: 15 | C23: April Oil Ghana | D23: 13.99 | E23: - | F23: 17.7 | G23: - | H23: - | I23: -
B24: 16 | C24: Benab Oil | D24: 13.27 | E24: - | F24: 16.1 | G24: - | H24: - | I24: -
B25: 17 | C25: Baffour Gas | D25: - | E25: - | F25: - | G25: 15.5 | H25: - | I25: -
B26: 18 | C26: Beap Energy | D26: 13.73 | E26: - | F26: 17.39 | G26: - | H26: - | I26: -
B27: 19 | C27: BG Petroleum | D27: 13.85 | E27: - | F27: 17.97 | G27: - | H27: - | I27: -
B28: 20 | C28: Bloom Petroleum | D28: 13.99 | E28: - | F28: 16.99 | G28: - | H28: - | I28: -
B29: 21 | C29: Brogan Energy | D29: 13.57 | E29: - | F29: 15.55 | G29: - | H29: - | I29: -
B30: 22 | C30: Breedlove | D30: 13.27 | E30: - | F30: 16.1 | G30: - | H30: - | I30: -
B31: 23 | C31: Brent Petroleum | D31: 13.46 | E31: - | F31: 17.69 | G31: - | H31: - | I31: -
B32: 24 | C32: Buffallo | D32: 13.39 | E32: - | F32: 13.99 | G32: - | H32: - | I32: -
B33: 25 | C33: Central Brent | D33: - | E33: - | F33: - | G33: 14.11 | H33: - | I33: -
B34: 26 | C34: Cent Eastern | D34: - | E34: - | F34: - | G34: 17.01 | H34: - | I34: -
B35: 27 | C35: Oil Space | D35: - | E35: - | F35: - | G35: 14.84 | H35: - | I35: -
B36: 28 | C36: Coegan | D36: - | E36: - | F36: - | G36: 17.16 | H36: - | I36: -
B37: 29 | C37: Compass Oleum | D37: 13.85 | E37: - | F37: 16.75 | G37: - | H37: - | I37: -
B38: 30 | C38: Crown Petroleum | D38: 14.32 | E38: - | F38: 18.1 | G38: 18.53 | H38: - | I38: -
B39: 31 | C39: Desert oil | D39: 13.59 | E39: - | F39: 17.69 | G39: - | H39: - | I39: -
B40: 32 | C40: Dejon jones Ltd | D40: 14.21 | E40: - | F40: 16.95 | G40: - | H40: - | I40: -
B41: 33 | C41: Davis Petroleum | D41: 13.99 | E41: - | F41: 16.99 | G41: 15.21 | H41: - | I41: -
B42: 34 | C42: Dukes Petroleum | D42: 13.3 | E42: - | F42: 17.1 | G42: 14.11 | H42: - | I42: -
B43: 35 | C43: E. Windstar Petroleum | D43: 13.55 | E43: - | F43: 16.99 | G43: =G9 -> - | H43: - | I43: -
B44: 36 | C44: Eden Petroleum | D44: 13.45 | E44: - | F44: 17.1 | G44: - | H44: - | I44: -
B45: 37 | C45: Essence Energy | D45: 14.3 | E45: - | F45: 18.3 | G45: - | H45: - | I45: -
...

Sheet Ex-Pump Prices 17th April 2026
B2: NATIONAL PETROLEUM AUTHORITY
B6: EX-PUMP PRICES OF OMCs/LPGMCs AS OF 17th APRIL 2026
B8: NO. | C8: COMPANY | D8: REGULAR PETROL - RON 91 (GHS/Lt) | E8: PREMIUM PETROL - RON 95 (GHS/Lt) | F8: DIESEL (GHS/Lt) | G8: LPG (GHS/Kg) | H8: KEROSENE (GHS/Lt) | I8: MGO Local (GHS/Lt)
B9: 1 | C9: Agapet | D9: 14.46 | E9: - | F9: 16.95 | G9: - | H9: - | I9: -
B10: 2 | C10: Aegis huile | D10: 13.5 | E10: - | F10: 17.5 | G10: - | H10: - | I10: -
B11: 3 | C11: Akara Energy | D11: 13.07 | E11: - | F11: 16.05 | G11: - | H11: - | I11: -
B12: 4 | C12: AI Energy | D12: 13.89 | E12: - | F12: 16.99 | G12: - | H12: - | I12: -
B13: 5 | C13: Allied Oil | D13: 13.3 | E13: - | F13: 17.5 | G13: - | H13: - | I13: -
B14: 6 | C14: Alinco | D14: 13.27 | E14: - | F14: 16.1 | G14: - | H14: - | I14: -
B15: 7 | C15: Alive Gas | D15: - | E15: - | F15: - | G15: 15.81 | H15: - | I15: -
B16: 8 | C16: Aminso Energy | D16: 12 | E16: - | F16: 12.58 | G16: - | H16: - | I16: -
B17: 9 | C17: Anasset | D17: =-J5 -> 0 | E17: - | F17: - | G17: 16.7 | H17: - | I17: -
B18: 10 | C18: Andev | D18: - | E18: - | F18: - | G18: 16.76 | H18: - | I18: -
B19: 11 | C19: Annandale | D19: - | E19: - | F19: - | G19: 16.61 | H19: - | I19: -
B20: 12 | C20: Amdaway | D20: 13.56 | E20: - | F20: 17.56 | G20: - | H20: - | I20: -
B21: 13 | C21: Aminaser oil | D21: 13.3 | E21: - | F21: 17.1 | G21: - | H21: - | I21: -
B22: 14 | C22: Ap Oil & Gas | D22: 13.55 | E22: - | F22: 17.4 | G22: - | H22: - | I22: -
B23: 15 | C23: April Oil Ghana | D23: 13.99 | E23: - | F23: 17.7 | G23: - | H23: - | I23: -
B24: 16 | C24: Benab Oil | D24: 13.27 | E24: - | F24: 16.1 | G24: - | H24: - | I24: -
B25: 17 | C25: Baffour Gas | D25: - | E25: - | F25: - | G25: 15.5 | H25: - | I25: -
B26: 18 | C26: Beap Energy | D26: 13.73 | E26: - | F26: 17.39 | G26: - | H26: - | I26: -
B27: 19 | C27: BG Petroleum | D27: 13.85 | E27: - | F27: 17.97 | G27: - | H27: - | I27: -
B28: 20 | C28: Bloom Petroleum | D28: 14.29 | E28: - | F28: 17.99 | G28: - | H28: - | I28: -
B29: 21 | C29: Brogan Energy | D29: 13.57 | E29: - | F29: 15.55 | G29: - | H29: - | I29: -
B30: 22 | C30: Breedlove | D30: 13.5 | E30: - | F30: 17.5 | G30: - | H30: - | I30: -
B31: 23 | C31: Brent Petroleum | D31: 13.46 | E31: - | F31: 17.69 | G31: - | H31: - | I31: -
B32: 24 | C32: Buffallo | D32: 13.39 | E32: - | F32: 13.99 | G32: - | H32: - | I32: -
B33: 25 | C33: Central Brent | D33: - | E33: - | F33: - | G33: 14.11 | H33: - | I33: -
B34: 26 | C34: Cent Eastern | D34: - | E34: - | F34: - | G34: 17.01 | H34: - | I34: -
B35: 27 | C35: Oil Space | D35: - | E35: - | F35: - | G35: 14.84 | H35: - | I35: -
B36: 28 | C36: Coegan | D36: - | E36: - | F36: - | G36: 17.16 | H36: - | I36: -
B37: 29 | C37: Compass Oleum | D37: 13.85 | E37: - | F37: 16.75 | G37: - | H37: - | I37: -
B38: 30 | C38: Crown Petroleum | D38: 14.32 | E38: - | F38: 18.1 | G38: 18.53 | H38: - | I38: -
B39: 31 | C39: Desert oil | D39: 13.59 | E39: - | F39: 17.69 | G39: - | H39: - | I39: -
B40: 32 | C40: Dejon jones Ltd | D40: 14.21 | E40: - | F40: 16.95 | G40: - | H40: - | I40: -
B41: 33 | C41: Davis Petroleum | D41: 13.99 | E41: - | F41: 16.99 | G41: 15.21 | H41: - | I41: -
B42: 34 | C42: Dukes Petroleum | D42: 13.3 | E42: - | F42: 17.1 | G42: 14.11 | H42: - | I42: -
B43: 35 | C43: E. Windstar Petroleum | D43: 13.8 | E43: - | F43: 18.4 | G43: =G9 -> - | H43: - | I43: -
B44: 36 | C44: Eden Petroleum | D44: 13.45 | E44: - | F44: 17.1 | G44: - | H44: - | I44: -
B45: 37 | C45: Essence Energy | D45: 14.3 | E45: - | F45: 18.3 | G45: - | H45: - | I45: -
...

Sheet Ex-Pump Prices 16th April 2026
B2: NATIONAL PETROLEUM AUTHORITY
B6: EX-PUMP PRICES OF OMCs/LPGMCs AS OF 16th APRIL 2026
B8: NO. | C8: COMPANY | D8: REGULAR PETROL - RON 91 (GHS/Lt) | E8: PREMIUM PETROL - RON 95 (GHS/Lt) | F8: DIESEL (GHS/Lt) | G8: LPG (GHS/Kg) | H8: KEROSENE (GHS/Lt) | I8: MGO Local (GHS/Lt)
B9: 1 | C9: Agapet | D9: 14.46 | E9: - | F9: 16.95 | G9: - | H9: - | I9: -
B10: 2 | C10: Aegis huile | D10: 13.39 | E10: - | F10: 16.1 | G10: - | H10: - | I10: -
B11: 3 | C11: Akara Energy | D11: 13.07 | E11: - | F11: 16.05 | G11: - | H11: - | I11: -
B12: 4 | C12: AI Energy | D12: 13.89 | E12: - | F12: 16.99 | G12: - | H12: - | I12: -
B13: 5 | C13: Allied Oil | D13: 13.3 | E13: - | F13: 17.5 | G13: - | H13: - | I13: -
B14: 6 | C14: Alinco | D14: 13.3 | E14: - | F14: 17.1 | G14: - | H14: - | I14: -
B15: 7 | C15: Alive Gas | D15: - | E15: - | F15: - | G15: 15.81 | H15: - | I15: -
B16: 8 | C16: Aminso Energy | D16: 12 | E16: - | F16: 12.58 | G16: - | H16: - | I16: -
B17: 9 | C17: Anasset | D17: =-J5 -> 0 | E17: - | F17: - | G17: 16.7 | H17: - | I17: -
B18: 10 | C18: Andev | D18: - | E18: - | F18: - | G18: 14.91 | H18: - | I18: -
B19: 11 | C19: Annandale | D19: - | E19: - | F19: - | G19: 16.61 | H19: - | I19: -
B20: 12 | C20: Amdaway | D20: 13.56 | E20: - | F20: 17.56 | G20: - | H20: - | I20: -
B21: 13 | C21: Aminaser oil | D21: 13.3 | E21: - | F21: 17.1 | G21: - | H21: - | I21: -
B22: 14 | C22: Ap Oil & Gas | D22: 13.55 | E22: - | F22: 17.4 | G22: - | H22: - | I22: -
B23: 15 | C23: April Oil Ghana | D23: 13.99 | E23: - | F23: 17.7 | G23: - | H23: - | I23: -
B24: 16 | C24: Benab Oil | D24: 13.3 | E24: - | F24: 17.1 | G24: - | H24: - | I24: -
B25: 17 | C25: Baffour Gas | D25: - | E25: - | F25: - | G25: 15.5 | H25: - | I25: -
B26: 18 | C26: Beap Energy | D26: 13.83 | E26: - | F26: 16.99 | G26: - | H26: - | I26: -
B27: 19 | C27: BG Petroleum | D27: 13.85 | E27: - | F27: 17.97 | G27: - | H27: - | I27: -
B28: 20 | C28: Bloom Petroleum | D28: 14.29 | E28: - | F28: 17.99 | G28: - | H28: - | I28: -
B29: 21 | C29: Brogan Energy | D29: 13.57 | E29: - | F29: 15.55 | G29: - | H29: - | I29: -
B30: 22 | C30: Breedlove | D30: 13.5 | E30: - | F30: 17.5 | G30: - | H30: - | I30: -
B31: 23 | C31: Brent Petroleum | D31: 13.46 | E31: - | F31: 17.69 | G31: - | H31: - | I31: -
B32: 24 | C32: Buffallo | D32: 13.39 | E32: - | F32: 13.99 | G32: - | H32: - | I32: -
B33: 25 | C33: Central Brent | D33: - | E33: - | F33: - | G33: 14.11 | H33: - | I33: -
B34: 26 | C34: Cent Eastern | D34: - | E34: - | F34: - | G34: 17.01 | H34: - | I34: -
B35: 27 | C35: Oil Space | D35: - | E35: - | F35: - | G35: 14.84 | H35: - | I35: -
B36: 28 | C36: Coegan | D36: - | E36: - | F36: - | G36: 17.16 | H36: - | I36: -
B37: 29 | C37: Compass Oleum | D37: 14.2 | E37: - | F37: 17.9 | G37: - | H37: - | I37: -
B38: 30 | C38: Crown Petroleum | D38: 14.32 | E38: - | F38: 18.1 | G38: 18.53 | H38: - | I38: -
B39: 31 | C39: Desert oil | D39: 13.59 | E39: - | F39: 17.69 | G39: - | H39: - | I39: -
B40: 32 | C40: Dejon jones Ltd | D40: 14.21 | E40: - | F40: 16.95 | G40: - | H40: - | I40: -
B41: 33 | C41: Davis Petroleum | D41: 13.99 | E41: - | F41: 17.7 | G41: 15.21 | H41: - | I41: -
B42: 34 | C42: Dukes Petroleum | D42: 13.3 | E42: - | F42: 17.1 | G42: 14.11 | H42: - | I42: -
B43: 35 | C43: E. Windstar Petroleum | D43: 13.8 | E43: - | F43: 18.4 | G43: =G9 -> - | H43: - | I43: -
B44: 36 | C44: Eden Petroleum | D44: 13.45 | E44: - | F44: 17.1 | G44: - | H44: - | I44: -
B45: 37 | C45: Essence Energy | D45: 14.3 | E45: - | F45: 18.3 | G45: - | H45: - | I45: -
...

Sheet Ex-Pump Prices 15th April 2026
B2: NATIONAL PETROLEUM AUTHORITY
B6: EX-PUMP PRICES OF OMCs/LPGMCs AS OF 15th APRIL 2026
B8: NO. | C8: COMPANY | D8: REGULAR PETROL - RON 91 (GHS/Lt) | E8: PREMIUM PETROL - RON 95 (GHS/Lt) | F8: DIESEL (GHS/Lt) | G8: LPG (GHS/Kg) | H8: KEROSENE (GHS/Lt) | I8: MGO Local (GHS/Lt)
B9: 1 | C9: Agapet | D9: 14.72 | E9: - | F9: 18.1 | G9: - | H9: - | I9: -
B10: 2 | C10: Aegis huile | D10: 13.5 | E10: - | F10: 17.5 | G10: - | H10: - | I10: -
B11: 3 | C11: Akara Energy | D11: 13.07 | E11: - | F11: 16.05 | G11: - | H11: - | I11: -
B12: 4 | C12: AI Energy | D12: 13.89 | E12: - | F12: 17.99 | G12: - | H12: - | I12: -
B13: 5 | C13: Allied Oil | D13: 13.3 | E13: - | F13: 17.5 | G13: - | H13: - | I13: -
B14: 6 | C14: Alinco | D14: 13.3 | E14: - | F14: 17.1 | G14: - | H14: - | I14: -
B15: 7 | C15: Alive Gas | D15: - | E15: - | F15: - | G15: 15.81 | H15: - | I15: -
B16: 8 | C16: Aminso Energy | D16: 12 | E16: - | F16: 12.58 | G16: - | H16: - | I16: -
B17: 9 | C17: Anasset | D17: =-J5 -> 0 | E17: - | F17: - | G17: 15.3 | H17: - | I17: -
B18: 10 | C18: Andev | D18: - | E18: - | F18: - | G18: 14.91 | H18: - | I18: -
B19: 11 | C19: Annandale | D19: - | E19: - | F19: - | G19: 14.94 | H19: - | I19: -
B20: 12 | C20: Amdaway | D20: 13.56 | E20: - | F20: 17.56 | G20: - | H20: - | I20: -
B21: 13 | C21: Aminaser oil | D21: 13.3 | E21: - | F21: 17.1 | G21: - | H21: - | I21: -
B22: 14 | C22: Ap Oil & Gas | D22: 13.55 | E22: - | F22: 17.4 | G22: - | H22: - | I22: -
B23: 15 | C23: April Oil Ghana | D23: 13.99 | E23: - | F23: 17.7 | G23: - | H23: - | I23: -
B24: 16 | C24: Benab Oil | D24: 13.3 | E24: - | F24: 17.1 | G24: - | H24: - | I24: -
B25: 17 | C25: Baffour Gas | D25: - | E25: - | F25: - | G25: 15.5 | H25: - | I25: -
B26: 18 | C26: Beap Energy | D26: 13.79 | E26: - | F26: 18.6 | G26: - | H26: - | I26: -
B27: 19 | C27: BG Petroleum | D27: 13.85 | E27: - | F27: 17.97 | G27: - | H27: - | I27: -
B28: 20 | C28: Bloom Petroleum | D28: 14.29 | E28: - | F28: 17.99 | G28: - | H28: - | I28: -
B29: 21 | C29: Brogan Energy | D29: 13.57 | E29: - | F29: 15.55 | G29: - | H29: - | I29: -
B30: 22 | C30: Breedlove | D30: 13.5 | E30: - | F30: 17.5 | G30: - | H30: - | I30: -
B31: 23 | C31: Brent Petroleum | D31: 13.49 | E31: - | F31: 17.69 | G31: - | H31: - | I31: -
B32: 24 | C32: Buffallo | D32: 13.39 | E32: - | F32: 13.99 | G32: - | H32: - | I32: -
B33: 25 | C33: Central Brent | D33: - | E33: - | F33: - | G33: 14.11 | H33: - | I33: -
B34: 26 | C34: Cent Eastern | D34: - | E34: - | F34: - | G34: 14.83 | H34: - | I34: -
B35: 27 | C35: Oil Space | D35: - | E35: - | F35: - | G35: 14.84 | H35: - | I35: -
B36: 28 | C36: Coegan | D36: - | E36: - | F36: - | G36: 15.26 | H36: - | I36: -
B37: 29 | C37: Compass Oleum | D37: 14.2 | E37: - | F37: 17.9 | G37: - | H37: - | I37: -
B38: 30 | C38: Crown Petroleum | D38: 14.32 | E38: - | F38: 18.1 | G38: 18.53 | H38: - | I38: -
B39: 31 | C39: Desert oil | D39: 13.59 | E39: - | F39: 17.69 | G39: - | H39: - | I39: -
B40: 32 | C40: Dejon jones Ltd | D40: 14.57 | E40: - | F40: 18.65 | G40: - | H40: - | I40: -
B41: 33 | C41: Davis Petroleum | D41: 13.99 | E41: - | F41: 17.7 | G41: 15.21 | H41: - | I41: -
B42: 34 | C42: Dukes Petroleum | D42: 13.5 | E42: - | F42: 17.6 | G42: 15.16 | H42: - | I42: -
B43: 35 | C43: E. Windstar Petroleum | D43: 13.8 | E43: - | F43: 18.4 | G43: =G9 -> - | H43: - | I43: -
B44: 36 | C44: Eden Petroleum | D44: 14.49 | E44: - | F44: 17.99 | G44: - | H44: - | I44: -
B45: 37 | C45: Essence Energy | D45: 14.3 | E45: - | F45: 18.3 | G45: - | H45: - | I45: -
...

Sheet Ex-Pump Prices 14th April 2026
B2: NATIONAL PETROLEUM AUTHORITY
B6: EX-PUMP PRICES OF OMCs/LPGMCs AS OF 14th APRIL 2026
B8: NO. | C8: COMPANY | D8: REGULAR PETROL - RON 91 (GHS/Lt) | E8: PREMIUM PETROL - RON 95 (GHS/Lt) | F8: DIESEL (GHS/Lt) | G8: LPG (GHS/Kg) | H8: KEROSENE (GHS/Lt) | I8: MGO Local (GHS/Lt)
B9: 1 | C9: Agapet | D9: 14.72 | E9: - | F9: 18.1 | G9: - | H9: - | I9: -
B10: 2 | C10: Aegis huile | D10: 13.5 | E10: - | F10: 17.5 | G10: - | H10: - | I10: -
B11: 3 | C11: Akara Energy | D11: 13.07 | E11: - | F11: 16.05 | G11: - | H11: - | I11: -
B12: 4 | C12: AI Energy | D12: 13.89 | E12: - | F12: 17.99 | G12: - | H12: - | I12: -
B13: 5 | C13: Allied Oil | D13: 13.3 | E13: - | F13: 17.5 | G13: - | H13: - | I13: -
B14: 6 | C14: Alinco | D14: 13.3 | E14: - | F14: 17.1 | G14: - | H14: - | I14: -
B15: 7 | C15: Alive Gas | D15: - | E15: - | F15: - | G15: 15.81 | H15: - | I15: -
B16: 8 | C16: Aminso Energy | D16: 12 | E16: - | F16: 12.58 | G16: - | H16: - | I16: -
B17: 9 | C17: Anasset | D17: =-J5 -> 0 | E17: - | F17: - | G17: 15.3 | H17: - | I17: -
B18: 10 | C18: Andev | D18: - | E18: - | F18: - | G18: 14.91 | H18: - | I18: -
B19: 11 | C19: Annandale | D19: - | E19: - | F19: - | G19: 14.94 | H19: - | I19: -
B20: 12 | C20: Amdaway | D20: 13.56 | E20: - | F20: 17.56 | G20: - | H20: - | I20: -
B21: 13 | C21: Aminaser oil | D21: 13.3 | E21: - | F21: 17.1 | G21: - | H21: - | I21: -
B22: 14 | C22: Ap Oil & Gas | D22: 12.2 | E22: - | F22: 12.8 | G22: - | H22: - | I22: -
B23: 15 | C23: April Oil Ghana | D23: 13.99 | E23: - | F23: 17.7 | G23: - | H23: - | I23: -
B24: 16 | C24: Benab Oil | D24: 13.3 | E24: - | F24: 17.1 | G24: - | H24: - | I24: -
B25: 17 | C25: Baffour Gas | D25: - | E25: - | F25: - | G25: 15.5 | H25: - | I25: -
B26: 18 | C26: Beap Energy | D26: 16.07 | E26: - | F26: 18.6 | G26: - | H26: - | I26: -
B27: 19 | C27: BG Petroleum | D27: 13.85 | E27: - | F27: 17.97 | G27: - | H27: - | I27: -
B28: 20 | C28: Bloom Petroleum | D28: 14.29 | E28: - | F28: 17.99 | G28: - | H28: - | I28: -
B29: 21 | C29: Brogan Energy | D29: 13.57 | E29: - | F29: 15.55 | G29: - | H29: - | I29: -
B30: 22 | C30: Breedlove | D30: 13.5 | E30: - | F30: 17.5 | G30: - | H30: - | I30: -
B31: 23 | C31: Brent Petroleum | D31: 13.49 | E31: - | F31: 17.69 | G31: - | H31: - | I31: -
B32: 24 | C32: Buffallo | D32: 13.39 | E32: - | F32: 13.99 | G32: - | H32: - | I32: -
B33: 25 | C33: Central Brent | D33: - | E33: - | F33: - | G33: 14.11 | H33: - | I33: -
B34: 26 | C34: Cent Eastern | D34: - | E34: - | F34: - | G34: 14.83 | H34: - | I34: -
B35: 27 | C35: Oil Space | D35: - | E35: - | F35: - | G35: 14.84 | H35: - | I35: -
B36: 28 | C36: Coegan | D36: - | E36: - | F36: - | G36: 15.26 | H36: - | I36: -
B37: 29 | C37: Compass Oleum | D37: 14.2 | E37: - | F37: 17.9 | G37: - | H37: - | I37: -
B38: 30 | C38: Crown Petroleum | D38: 14.32 | E38: - | F38: 18.1 | G38: 18.53 | H38: - | I38: -
B39: 31 | C39: Desert oil | D39: 13.19 | E39: - | F39: 15.79 | G39: - | H39: - | I39: -
B40: 32 | C40: Dejon jones Ltd | D40: 14.57 | E40: - | F40: 18.65 | G40: - | H40: - | I40: -
B41: 33 | C41: Davis Petroleum | D41: 13.99 | E41: - | F41: 17.7 | G41: 15.21 | H41: - | I41: -
B42: 34 | C42: Dukes Petroleum | D42: 13.5 | E42: - | F42: 17.6 | G42: 15.16 | H42: - | I42: -
B43: 35 | C43: E. Windstar Petroleum | D43: 13.8 | E43: - | F43: 18.4 | G43: =G9 -> - | H43: - | I43: -
B44: 36 | C44: Eden Petroleum | D44: 14.49 | E44: - | F44: 17.99 | G44: - | H44: - | I44: -
B45: 37 | C45: Essence Energy | D45: 14.3 | E45: - | F45: 18.3 | G45: - | H45: - | I45: -
...

Sheet Ex-Pump Prices 13th April 2026
B2: NATIONAL PETROLEUM AUTHORITY
B6: EX-PUMP PRICES OF OMCs/LPGMCs AS OF 13th APRIL 2026
B8: NO. | C8: COMPANY | D8: REGULAR PETROL - RON 91 (GHS/Lt) | E8: PREMIUM PETROL - RON 95 (GHS/Lt) | F8: DIESEL (GHS/Lt) | G8: LPG (GHS/Kg) | H8: KEROSENE (GHS/Lt) | I8: MGO Local (GHS/Lt)
B9: 1 | C9: Agapet | D9: 14.72 | E9: - | F9: 18.1 | G9: - | H9: - | I9: -
B10: 2 | C10: Aegis huile | D10: 13.5 | E10: - | F10: 17.5 | G10: - | H10: - | I10: -
B11: 3 | C11: Akara Energy | D11: 13.07 | E11: - | F11: 16.05 | G11: - | H11: - | I11: -
B12: 4 | C12: AI Energy | D12: 13.89 | E12: - | F12: 17.99 | G12: - | H12: - | I12: -
B13: 5 | C13: Allied Oil | D13: 13.3 | E13: - | F13: 17.5 | G13: - | H13: - | I13: -
B14: 6 | C14: Alinco | D14: 13.3 | E14: - | F14: 17.1 | G14: - | H14: - | I14: -
B15: 7 | C15: Alive Gas | D15: - | E15: - | F15: - | G15: 15.81 | H15: - | I15: -
B16: 8 | C16: Aminso Energy | D16: 12 | E16: - | F16: 12.58 | G16: - | H16: - | I16: -
B17: 9 | C17: Anasset | D17: =-J5 -> 0 | E17: - | F17: - | G17: 15.3 | H17: - | I17: -
B18: 10 | C18: Andev | D18: - | E18: - | F18: - | G18: 14.91 | H18: - | I18: -
B19: 11 | C19: Annandale | D19: - | E19: - | F19: - | G19: 14.94 | H19: - | I19: -
B20: 12 | C20: Amdaway | D20: 13.56 | E20: - | F20: 17.56 | G20: - | H20: - | I20: -
B21: 13 | C21: Aminaser oil | D21: 13.3 | E21: - | F21: 17.1 | G21: - | H21: - | I21: -
B22: 14 | C22: Ap Oil & Gas | D22: 12.2 | E22: - | F22: 12.8 | G22: - | H22: - | I22: -
B23: 15 | C23: April Oil Ghana | D23: 13.99 | E23: - | F23: 17.7 | G23: - | H23: - | I23: -
B24: 16 | C24: Benab Oil | D24: 13.3 | E24: - | F24: 17.1 | G24: - | H24: - | I24: -
B25: 17 | C25: Baffour Gas | D25: - | E25: - | F25: - | G25: 15.5 | H25: - | I25: -
B26: 18 | C26: Beap Energy | D26: 16.07 | E26: - | F26: 18.6 | G26: - | H26: - | I26: -
B27: 19 | C27: BG Petroleum | D27: 13.85 | E27: - | F27: 17.97 | G27: - | H27: - | I27: -
B28: 20 | C28: Bloom Petroleum | D28: 14.29 | E28: - | F28: 17.99 | G28: - | H28: - | I28: -
B29: 21 | C29: Brogan Energy | D29: 13.57 | E29: - | F29: 15.55 | G29: - | H29: - | I29: -
B30: 22 | C30: Breedlove | D30: 13.5 | E30: - | F30: 17.5 | G30: - | H30: - | I30: -
B31: 23 | C31: Brent Petroleum | D31: 13.49 | E31: - | F31: 17.69 | G31: - | H31: - | I31: -
B32: 24 | C32: Buffallo | D32: 13.39 | E32: - | F32: 13.99 | G32: - | H32: - | I32: -
B33: 25 | C33: Central Brent | D33: - | E33: - | F33: - | G33: 14.11 | H33: - | I33: -
B34: 26 | C34: Cent Eastern | D34: - | E34: - | F34: - | G34: 14.83 | H34: - | I34: -
B35: 27 | C35: Oil Space | D35: - | E35: - | F35: - | G35: 14.84 | H35: - | I35: -
B36: 28 | C36: Coegan | D36: - | E36: - | F36: - | G36: 15.26 | H36: - | I36: -
B37: 29 | C37: Compass Oleum | D37: 14.2 | E37: - | F37: 17.9 | G37: - | H37: - | I37: -
B38: 30 | C38: Crown Petroleum | D38: 14.32 | E38: - | F38: 18.1 | G38: 18.53 | H38: - | I38: -
B39: 31 | C39: Desert oil | D39: 13.19 | E39: - | F39: 15.79 | G39: - | H39: - | I39: -
B40: 32 | C40: Dejon jones Ltd | D40: 14.57 | E40: - | F40: 18.65 | G40: - | H40: - | I40: -
B41: 33 | C41: Davis Petroleum | D41: 13.99 | E41: - | F41: 17.7 | G41: 15.21 | H41: - | I41: -
B42: 34 | C42: Dukes Petroleum | D42: 13.5 | E42: - | F42: 17.6 | G42: 15.16 | H42: - | I42: -
B43: 35 | C43: E. Windstar Petroleum | D43: 13.8 | E43: - | F43: 18.4 | G43: =G9 -> - | H43: - | I43: -
B44: 36 | C44: Eden Petroleum | D44: 14.49 | E44: - | F44: 17.99 | G44: - | H44: - | I44: -
B45: 37 | C45: Essence Energy | D45: 14.3 | E45: - | F45: 18.3 | G45: - | H45: - | I45: -
...

Sheet Ex-Pump Prices 10th April 2026
B2: NATIONAL PETROLEUM AUTHORITY
B6: EX-PUMP PRICES OF OMCs/LPGMCs AS OF 10th APRIL 2026
B8: NO. | C8: COMPANY | D8: REGULAR PETROL - RON 91 (GHS/Lt) | E8: PREMIUM PETROL - RON 95 (GHS/Lt) | F8: DIESEL (GHS/Lt) | G8: LPG (GHS/Kg) | H8: KEROSENE (GHS/Lt) | I8: MGO Local (GHS/Lt)
B9: 1 | C9: Agapet | D9: 14.72 | E9: - | F9: 18.1 | G9: - | H9: - | I9: -
B10: 2 | C10: Aegis huile | D10: 13.5 | E10: - | F10: 17.5 | G10: - | H10: - | I10: -
B11: 3 | C11: Akara Energy | D11: 13.07 | E11: - | F11: 16.05 | G11: - | H11: - | I11: -
B12: 4 | C12: AI Energy | D12: 13.89 | E12: - | F12: 17.99 | G12: - | H12: - | I12: -
B13: 5 | C13: Allied Oil | D13: 13.3 | E13: - | F13: 17.5 | G13: - | H13: - | I13: -
B14: 6 | C14: Alinco | D14: 13.56 | E14: - | F14: 17.56 | G14: - | H14: - | I14: -
B15: 7 | C15: Alive Gas | D15: - | E15: - | F15: - | G15: 15.81 | H15: - | I15: -
B16: 8 | C16: Aminso Energy | D16: 12 | E16: - | F16: 12.58 | G16: - | H16: - | I16: -
B17: 9 | C17: Anasset | D17: =-J5 -> 0 | E17: - | F17: - | G17: 15.3 | H17: - | I17: -
B18: 10 | C18: Andev | D18: - | E18: - | F18: - | G18: 14.91 | H18: - | I18: -
B19: 11 | C19: Annandale | D19: - | E19: - | F19: - | G19: 14.94 | H19: - | I19: -
B20: 12 | C20: Amdaway | D20: 13.56 | E20: - | F20: 17.56 | G20: - | H20: - | I20: -
B21: 13 | C21: Aminaser oil | D21: 13.3 | E21: - | F21: 17.1 | G21: - | H21: - | I21: -
B22: 14 | C22: Ap Oil & Gas | D22: 12.2 | E22: - | F22: 12.8 | G22: - | H22: - | I22: -
B23: 15 | C23: April Oil Ghana | D23: 13.99 | E23: - | F23: 17.7 | G23: - | H23: - | I23: -
B24: 16 | C24: Benab Oil | D24: 13.3 | E24: - | F24: 17.1 | G24: - | H24: - | I24: -
B25: 17 | C25: Baffour Gas | D25: - | E25: - | F25: - | G25: 15.5 | H25: - | I25: -
B26: 18 | C26: Beap Energy | D26: 16.07 | E26: - | F26: 18.6 | G26: - | H26: - | I26: -
B27: 19 | C27: BG Petroleum | D27: 13.85 | E27: - | F27: 17.97 | G27: - | H27: - | I27: -
B28: 20 | C28: Bloom Petroleum | D28: 13.99 | E28: - | F28: 17.99 | G28: - | H28: - | I28: -
B29: 21 | C29: Brogan Energy | D29: 13.57 | E29: - | F29: 15.55 | G29: - | H29: - | I29: -
B30: 22 | C30: Breedlove | D30: 13.5 | E30: - | F30: 17.5 | G30: - | H30: - | I30: -
B31: 23 | C31: Brent Petroleum | D31: 13.49 | E31: - | F31: 17.69 | G31: - | H31: - | I31: -
B32: 24 | C32: Buffallo | D32: 13.39 | E32: - | F32: 13.99 | G32: - | H32: - | I32: -
B33: 25 | C33: Central Brent | D33: - | E33: - | F33: - | G33: 14.11 | H33: - | I33: -
B34: 26 | C34: Cent Eastern | D34: - | E34: - | F34: - | G34: 14.83 | H34: - | I34: -
B35: 27 | C35: Oil Space | D35: - | E35: - | F35: - | G35: 14.84 | H35: - | I35: -
B36: 28 | C36: Coegan | D36: - | E36: - | F36: - | G36: 15.26 | H36: - | I36: -
B37: 29 | C37: Compass Oleum | D37: 14.2 | E37: - | F37: 17.9 | G37: - | H37: - | I37: -
B38: 30 | C38: Crown Petroleum | D38: 14.32 | E38: - | F38: 18.1 | G38: 18.53 | H38: - | I38: -
B39: 31 | C39: Desert oil | D39: 13.19 | E39: - | F39: 15.79 | G39: - | H39: - | I39: -
B40: 32 | C40: Dejon jones Ltd | D40: 14.57 | E40: - | F40: 18.65 | G40: - | H40: - | I40: -
B41: 33 | C41: Davis Petroleum | D41: 13.99 | E41: - | F41: 17.7 | G41: 15.21 | H41: - | I41: -
B42: 34 | C42: Dukes Petroleum | D42: 13.5 | E42: - | F42: 17.6 | G42: 15.16 | H42: - | I42: -
B43: 35 | C43: E. Windstar Petroleum | D43: 13.8 | E43: - | F43: 18.4 | G43: =G9 -> - | H43: - | I43: -
B44: 36 | C44: Eden Petroleum | D44: 14.49 | E44: - | F44: 17.99 | G44: - | H44: - | I44: -
B45: 37 | C45: Essence Energy | D45: 14.3 | E45: - | F45: 18.3 | G45: - | H45: - | I45: -
...

Sheet Ex-Pump Prices 9th April 2026
B2: NATIONAL PETROLEUM AUTHORITY
B6: EX-PUMP PRICES OF OMCs/LPGMCs AS OF 7th APRIL 2026
B8: NO. | C8: COMPANY | D8: REGULAR PETROL - RON 91 (GHS/Lt) | E8: PREMIUM PETROL - RON 95 (GHS/Lt) | F8: DIESEL (GHS/Lt) | G8: LPG (GHS/Kg) | H8: KEROSENE (GHS/Lt) | I8: MGO Local (GHS/Lt)
B9: 1 | C9: Agapet | D9: 14.72 | E9: - | F9: 18.1 | G9: - | H9: - | I9: -
B10: 2 | C10: Aegis huile | D10: 13.5 | E10: - | F10: 17.5 | G10: - | H10: - | I10: -
B11: 3 | C11: Akara Energy | D11: 13.07 | E11: - | F11: 16.05 | G11: - | H11: - | I11: -
B12: 4 | C12: AI Energy | D12: 13.89 | E12: - | F12: 17.99 | G12: - | H12: - | I12: -
B13: 5 | C13: Allied Oil | D13: 13.3 | E13: - | F13: 17.5 | G13: - | H13: - | I13: -
B14: 6 | C14: Alinco | D14: 13.56 | E14: - | F14: 17.56 | G14: - | H14: - | I14: -
B15: 7 | C15: Alive Gas | D15: - | E15: - | F15: - | G15: 15.81 | H15: - | I15: -
B16: 8 | C16: Aminso Energy | D16: 12 | E16: - | F16: 12.58 | G16: - | H16: - | I16: -
B17: 9 | C17: Anasset | D17: =-J5 -> 0 | E17: - | F17: - | G17: 15.3 | H17: - | I17: -
B18: 10 | C18: Andev | D18: - | E18: - | F18: - | G18: 14.91 | H18: - | I18: -
B19: 11 | C19: Annandale | D19: - | E19: - | F19: - | G19: 14.94 | H19: - | I19: -
B20: 12 | C20: Amdaway | D20: 13.56 | E20: - | F20: 17.56 | G20: - | H20: - | I20: -
B21: 13 | C21: Aminaser oil | D21: 13.3 | E21: - | F21: 17.1 | G21: - | H21: - | I21: -
B22: 14 | C22: Ap Oil & Gas | D22: 12.2 | E22: - | F22: 12.8 | G22: - | H22: - | I22: -
B23: 15 | C23: April Oil Ghana | D23: 13.99 | E23: - | F23: 17.7 | G23: - | H23: - | I23: -
B24: 16 | C24: Benab Oil | D24: 13.3 | E24: - | F24: 17.1 | G24: - | H24: - | I24: -
B25: 17 | C25: Baffour Gas | D25: - | E25: - | F25: - | G25: 15.5 | H25: - | I25: -
B26: 18 | C26: Beap Energy | D26: 16.07 | E26: - | F26: 18.6 | G26: - | H26: - | I26: -
B27: 19 | C27: BG Petroleum | D27: 13.57 | E27: - | F27: 15.49 | G27: - | H27: - | I27: -
B28: 20 | C28: Bloom Petroleum | D28: 13.99 | E28: - | F28: 17.99 | G28: - | H28: - | I28: -
B29: 21 | C29: Brogan Energy | D29: 13.57 | E29: - | F29: 15.55 | G29: - | H29: - | I29: -
B30: 22 | C30: Breedlove | D30: 13.5 | E30: - | F30: 17.5 | G30: - | H30: - | I30: -
B31: 23 | C31: Brent Petroleum | D31: 13.49 | E31: - | F31: 17.69 | G31: - | H31: - | I31: -
B32: 24 | C32: Buffallo | D32: 13.39 | E32: - | F32: 13.99 | G32: - | H32: - | I32: -
B33: 25 | C33: Central Brent | D33: - | E33: - | F33: - | G33: 14.11 | H33: - | I33: -
B34: 26 | C34: Cent Eastern | D34: - | E34: - | F34: - | G34: 14.83 | H34: - | I34: -
B35: 27 | C35: Oil Space | D35: - | E35: - | F35: - | G35: 14.84 | H35: - | I35: -
B36: 28 | C36: Coegan | D36: - | E36: - | F36: - | G36: 15.26 | H36: - | I36: -
B37: 29 | C37: Compass Oleum | D37: 14.62 | E37: - | F37: 18.45 | G37: - | H37: - | I37: -
